<?xml version="1.2"?>
<robot name="origins">

<material name="green">
    <color rgba="0.05 0.8 0.2 0.9"/>
</material>    

  <link name="base_link">
    <visual>
      <geometry>
        <box size="0.3 0.65 1.912"/>
      </geometry>
      <material name="green"/>
      <origin rpy="0 0 0" xyz="0 0 1"/>
    </visual>
  </link>

  <link name="crane_boom">
    <visual>
      <geometry>
        <box size="3.68 0.1 0.15"/>
      </geometry>
      <origin rpy="0 0 0" xyz="1.76 0 0"/>
      <material name="green"/>
    </visual>
  </link>
  
  <link name="tool_link">
    <visual>
      <geometry>
        <box size="0.1 0.2 0.1"/>
      </geometry>
      <material name="green"/>
      <origin rpy="0 0 0" xyz="0 0 0"/>
    </visual>
  </link>

  <joint name="base_to_crane_boom" type="revolute">
    <axis xyz="0 1 0"/>
    <limit effort="1000.0" lower="0.3267" upper="-0.6948" velocity="0.5"/>
    <origin rpy="0 0 0" xyz="0 -0.22 1.8"/>
    <parent link="base_link"/>
    <child link="crane_boom"/>
  </joint>

  <joint name="tooltip" type="fixed">
    <parent link="crane_boom"/>
    <child link="tool_link"/>
    <origin xyz="3.68 0 0"/>
  </joint>
</robot>
